Workbook
Name ___wyb1: #REF!
Name ___wyb2: #REF!
Name ___wyb3: #REF!
Name ___wyb4: #REF!
Name ___wyb6: #REF!
Name __aa1: #REF!
Name __aq13: #REF!
Name __as5: #REF!
Name __sd32: #REF!
Name __wyb1: #REF!
Name __wyb2: #REF!
Name __wyb3: #REF!
Name __wyb4: #REF!
Name __wyb5: #REF!
Name __wyb6: #REF!
Name __xlnm.Print_Area_1: #REF!
Name _aa1: #REF!
Name _aq13: #REF!
Name _as5: #REF!
Name _bi2: [1]!bilans
Name _cf1: [1]!cf
Name _DAT1: #REF!
Name _DAT10: #REF!
Name _DAT11: #REF!
Name _DAT12: #REF!
Name _DAT13: #REF!
Name _DAT14: #REF!
Name _DAT15: #REF!
Name _DAT16: #REF!
Name _DAT17: #REF!
Name _DAT18: #REF!
Name _DAT19: #REF!
Name _DAT2: #REF!
Name _DAT20: #REF!
Name _DAT21: #REF!
Name _DAT22: #REF!
Name _DAT23: #REF!
Name _DAT24: #REF!
Name _DAT25: #REF!
Name _DAT26: #REF!
Name _DAT27: #REF!
Name _DAT28: #REF!
Name _DAT29: #REF!
Name _DAT3: #REF!
Name _DAT30: #REF!
Name _DAT31: #REF!
Name _DAT32: #REF!
Name _DAT33: #REF!
Name _DAT34: #REF!
Name _DAT35: #REF!
Name _DAT36: #REF!
Name _DAT37: #REF!
Name _DAT38: #REF!
Name _DAT4: #REF!
Name _DAT42: [2]Arkusz1!#REF!
Name _DAT5: #REF!
Name _DAT6: #REF!
Name _DAT7: #REF!
Name _DAT8: #REF!
Name _DAT9: #REF!

Sheet Sprzedaż
B1: Sprzedaż GK GA | D1: Wolumen sprzedaży - Plan 2027r. | I1: .
B2: ='[47]Plan - formuły oblicz'!B2
C4: styczeń | D4: luty | E4: marzec | F4: kwiecień | G4: maj | H4: czerwiec | I4: lipiec | J4: sierpień | K4: wrzesień | L4: październik | M4: listopad | N4: grudzień | O4: ∑
A5: ZAP | B5: ONECON ® | C5: 6200 | D5: 6200 | E5: 8700 | F5: 9500 | G5: 10200 | H5: 10200 | I5: 10200 | J5: 10200 | K5: 9400 | L5: 8400 | M5: 7000 | N5: 7000 | O5: =SUM(C5:N5) | P5: aktualne na 16.10.2026
A6: ZAP | B6: WODÓR [m3] | C6: 215 | D6: 215 | E6: 215 | F6: 215 | G6: 215 | H6: 215 | I6: 225 | J6: 225 | K6: 135 | L6: 215 | M6: 215 | N6: 215 | O6: =SUM(C6:N6)
A7: ZAP | B7: LIKAM ® | C7: 4200 | D7: 4000 | E7: 3800 | F7: 3300 | G7: 2500 | H7: 2500 | I7: 2500 | J7: 2500 | K7: 3200 | L7: 3800 | M7: 3800 | N7: 4000 | O7: =SUM(C7:N7)
A8: ZAP | B8: PULAN ® | C8: 40000 | D8: 38000 | E8: 48000 | F8: 45000 | G8: 34000 | H8: 28000 | I8: 30000 | J8: 24000 | K8: 36000 | L8: 40000 | M8: 42000 | N8: 41000 | O8: =SUM(C8:N8)
A9: ZAP | B9: MEGAN | C9: 40000 | D9: 34000 | E9: 41000 | F9: 22000 | G9: 19500 | H9: 18000 | I9: 23000 | J9: 37000 | K9: 38000 | L9: 39000 | M9: 35000 | N9: 36000 | O9: =SUM(C9:N9)
A10: ZAP | B10: PULAN ® MAKRO | C10: 2000 | D10: 1000 | E10: 1000 | F10: 1000 | G10: 1000 | H10: 1000 | I10: 1000 | J10: 2000 | K10: 1000 | L10: 1000 | M10: 1000 | N10: 2000 | O10: =SUM(C10:N10)
A11: ZAP | B11: PULMIX | O11: =SUM(C11:N11)
A12: ZAP | B12: SALMAG | C12: 3000 | D12: 4000 | E12: 4000 | F12: 4000 | G12: 1000 | H12: 4000 | I12: 4000 | J12: 9000 | K12: 8000 | L12: 8000 | M12: 8000 | N12: 8000 | O12: =SUM(C12:N12)
A13: ZAP | B13: eNpluS | C13: 5200 | D13: 5200 | E13: 5200 | F13: 5200 | G13: 5200 | H13: 5200 | I13: 5200 | J13: 5200 | K13: 5200 | L13: 5200 | M13: 5200 | N13: 5200 | O13: =SUM(C13:N13)
A14: ZAP | B14: RSM ® do sprzedaży | C14: 50000 | D14: 43000 | E14: 52000 | F14: 50000 | G14: 60200 | H14: 45000 | I14: 37400 | J14: 52200 | K14: 50000 | L14: 57900 | M14: 54000 | N14: 51000 | O14: =SUM(C14:N14)
A15: ZAP | B15: RSMS ® | C15: 10000 | D15: 10000 | E15: 8000 | F15: 10000 | G15: 5000 | H15: 5000 | I15: 5000 | J15: 5000 | K15: 8000 | L15: 10000 | M15: 10000 | N15: 10000 | O15: =SUM(C15:N15)
A16: ZAP | B16: PULREA ®(sprzedaż chemia) | C16: 7500 | D16: 7500 | E16: 9000 | F16: 10500 | G16: 13500 | H16: 13500 | I16: 13500 | J16: 13500 | K16: 11500 | L16: 8500 | M16: 7000 | N16: 4500 | O16: =SUM(C16:N16)
A17: ZAP | B17: PULREA ® +Inu (sprzedaż agro) | C17: 24000 | D17: 22000 | E17: 23600 | F17: 20000 | G17: 12200 | H17: 0 | I17: 0 | J17: 13000 | K17: 14000 | L17: 23000 | M17: 23500 | N17: 26600 | O17: =SUM(C17:N17)
A18: ZAP | B18: PULREA razem | C18: =C16+C17 | D18: =D16+D17 | E18: =E16+E17 | F18: =F16+F17 | G18: =G16+G17 | H18: =H16+H17 | I18: =I16+I17 | J18: =J16+J17 | ... N18: =N16+N17 | O18: =SUM(C18:N18)
A19: ZAP | B19: PULGRAN ® | O19: =SUM(C19:N19)
A20: ZAP | B20: Folires | O20: =SUM(C20:N20)
A21: ZAP | B21: eNTop | O21: =SUM(C21:N21)
A22: ZAP | B22: PULGRAN ® S 40N | O22: =SUM(C22:N22)
A23: ZAP | B23: PULGRAN ® S 36N | O23: =SUM(C23:N23)
A24: ZAP | B24: NOXy ® | C24: 14600 | D24: 14600 | E24: 16700 | F24: 17700 | G24: 17700 | H24: 17700 | I24: 20000 | J24: 20000 | K24: 20000 | L24: 19200 | M24: 17700 | N24: 14600 | O24: =SUM(C24:N24)
A25: ZAP | B25: PULNOX ® | C25: 1500 | D25: 1500 | E25: 1500 | F25: 2000 | G25: 2000 | H25: 1500 | I25: 1500 | J25: 1500 | K25: 1500 | L25: 1500 | M25: 1500 | N25: 1500 | O25: =SUM(C25:N25)
A26: ZAP | B26: MELAMINA ogółem | C26: =C27+C28+C29 | D26: =D27+D28+D29 | E26: =E27+E28+E29 | F26: =F27+F28+F29 | G26: =G27+G28+G29 | H26: =H27+H28+H29 | I26: =I27+I28+I29 | J26: =J27+J28+J29 | ... N26: =N27+N28+N29 | O26: =SUM(C26:N26) | P26: uzupełniono: suma Melaminy I+II+III
A27: ZAP | B27: MELAMINA I | O27: =SUM(C27:N27)
A28: ZAP | B28: MELAMINA II | O28: =SUM(C28:N28)
A29: ZAP | B29: MELAMINA III | O29: =SUM(C29:N29)
A30: ZAP | B30: KAPROLAKTAM | O30: =SUM(C30:N30)
A31: ZAP | B31: PULSAR ® | O31: =SUM(C31:N31)
A32: ZAP | B32: NADTLENEK WODORU | C32: 750 | D32: 750 | E32: 870 | F32: 870 | G32: 870 | H32: 870 | I32: 900 | J32: 900 | K32: 600 | L32: 800 | M32: 800 | N32: 800 | O32: =SUM(C32:N32)
A33: ZAP | B33: KWAS SIARKOWY - DO SPRZEDAŻY | C33: 5200 | D33: 5800 | E33: 6000 | F33: 6000 | G33: 6000 | H33: 6000 | I33: 6000 | J33: 6000 | K33: 6000 | L33: 6000 | M33: 6000 | N33: 5200 | O33: =SUM(C33:N33)
A34: ZAP | B34: IOS - SIARCZAN AMONU | C34: 800 | D34: 800 | E34: 750 | F34: 700 | G34: 600 | H34: 600 | I34: 800 | J34: 800 | K34: 800 | L34: 800 | M34: 800 | N34: 800 | O34: =SUM(C34:N34)
A35: ZAP | B35: KWAS AZOTOWY | C35: 1000 | D35: 1200 | E35: 2000 | F35: 1400 | G35: 2000 | H35: 2000 | I35: 2000 | J35: 2000 | K35: 2000 | L35: 1300 | M35: 1100 | N35: 1000 | O35: =SUM(C35:N35)
A36: ZAP | B36: COOLANT | C36: 310 | D36: 310 | E36: 310 | F36: 340 | G36: 380 | H36: 400 | I36: 420 | J36: 420 | K36: 380 | L36: 320 | M36: 310 | N36: 310 | O36: =SUM(C36:N36)
A37: ZAP | B37: AMONIAK | C37: 5 | D37: 5 | E37: 5 | F37: 10 | G37: 10 | H37: 10 | I37: 10 | J37: 10 | K37: 5 | L37: 5 | M37: 5 | N37: 5 | O37: =SUM(C37:N37)
A38: ZAP | B38: CO2 butle | C38: 4 | D38: 4 | E38: 4 | F38: 4 | G38: 4 | H38: 4 | I38: 4 | J38: 4 | K38: 4 | L38: 3 | M38: 3 | N38: 3 | O38: =SUM(C38:N38)
A39: ZAP | B39: POWIETRZE TECHNOLOGICZNE | C39: 300 | D39: 300 | E39: 300 | F39: 300 | G39: 300 | H39: 300 | I39: 300 | J39: 300 | K39: 300 | L39: 300 | M39: 300 | N39: 300 | O39: =SUM(C39:N39)
A41: ZAK | B41: AMONIAK sprzedaż | C41: =[48]Ilosc!D$5 | D41: =[48]Ilosc!E$5 | E41: =[48]Ilosc!F$5 | F41: =[48]Ilosc!G$5 | G41: =[48]Ilosc!H$5 | H41: =[48]Ilosc!I$5 | I41: =[48]Ilosc!J$5 | J41: =[48]Ilosc!K$5 | ... N41: =[48]Ilosc!O$5 | O41: =SUM(C41:N41)
A42: ZAK | B42: KWAS AZOTOWY SPRZEDAŻ | C42: =[48]Ilosc!D$8 | D42: =[48]Ilosc!E$8 | E42: =[48]Ilosc!F$8 | F42: =[48]Ilosc!G$8 | G42: =[48]Ilosc!H$8 | H42: =[48]Ilosc!I$8 | I42: =[48]Ilosc!J$8 | J42: =[48]Ilosc!K$8 | ... N42: =[48]Ilosc!O$8 | O42: =SUM(C42:N42)
...

Sheet Obliczenia
A1: Obliczenia dla każdego produktu – Plan sprzedaży 2027
A2: Numer wiersza = numer wiersza w arkuszu „Sprzedaż”. Kolumny E–F (żółte) to założenia: jednostka i czy produkt wchodzi do sumy ton spółki. Pozostałe kolumny to formuły.
A4: Spółka | B4: Produkt | C4: Status danych | D4: Liczba mies. z wolumenem | E4: Jednostka | F4: Do sumy ton (1/0) | G4: Q1 | H4: Q2 | I4: Q3 | J4: Q4 | K4: I półrocze | L4: II półrocze | M4: Rok | N4: Średnio / mies. | O4: Maks. mies. | P4: Min. mies. | Q4: Miesiąc szczytu | R4: Udział Q2+Q3 (sezon) | S4: Udział w tonach spółki | T4: Kontrola ∑ (Rok − kol. O) | U4: Klucz rankingu (pomocn.)
A5: ='Sprzedaż'!A5 | B5: ='Sprzedaż'!B5 | C5: =IF(COUNT('Sprzedaż'!C5:N5)=0,"BRAK DANYCH",IF(COUNT('Sprzedaż'!C5:N5)<12,"niepełne","komplet")) | D5: =COUNTIF('Sprzedaż'!C5:N5,">0.001") | E5: t | F5: 1 | G5: =SUM('Sprzedaż'!C5:E5) | H5: =SUM('Sprzedaż'!F5:H5) | I5: =SUM('Sprzedaż'!I5:K5) | J5: =SUM('Sprzedaż'!L5:N5) | K5: =G5+H5 | L5: =I5+J5 | M5: =SUM('Sprzedaż'!C5:N5) | N5: =IF(COUNT('Sprzedaż'!C5:N5)=0,0,M5/12) | O5: =MAX('Sprzedaż'!C5:N5) | P5: =MIN('Sprzedaż'!C5:N5) | Q5: =IF(M5<=0,"-",INDEX('Sprzedaż'!$C$4:$N$4,MATCH(O5,'Sprzedaż'!C5:N5,0))) | R5: =IF(M5<=0,0,(H5+I5)/M5) | S5: =IF(F5=0,"-",IFERROR(M5/SUMIFS($M$5:$M$138,$A$5:$A$138,A5,$F$5:$F$138,1),0)) | T5: =M5-N('Sprzedaż'!O5) | U5: =IF(F5=1,M5,-1)-ROW()/1000000
A6: ='Sprzedaż'!A6 | B6: ='Sprzedaż'!B6 | C6: =IF(COUNT('Sprzedaż'!C6:N6)=0,"BRAK DANYCH",IF(COUNT('Sprzedaż'!C6:N6)<12,"niepełne","komplet")) | D6: =COUNTIF('Sprzedaż'!C6:N6,">0.001") | E6: m3 | F6: 0 | G6: =SUM('Sprzedaż'!C6:E6) | H6: =SUM('Sprzedaż'!F6:H6) | I6: =SUM('Sprzedaż'!I6:K6) | J6: =SUM('Sprzedaż'!L6:N6) | K6: =G6+H6 | L6: =I6+J6 | M6: =SUM('Sprzedaż'!C6:N6) | N6: =IF(COUNT('Sprzedaż'!C6:N6)=0,0,M6/12) | O6: =MAX('Sprzedaż'!C6:N6) | P6: =MIN('Sprzedaż'!C6:N6) | Q6: =IF(M6<=0,"-",INDEX('Sprzedaż'!$C$4:$N$4,MATCH(O6,'Sprzedaż'!C6:N6,0))) | R6: =IF(M6<=0,0,(H6+I6)/M6) | S6: =IF(F6=0,"-",IFERROR(M6/SUMIFS($M$5:$M$138,$A$5:$A$138,A6,$F$5:$F$138,1),0)) | T6: =M6-N('Sprzedaż'!O6) | U6: =IF(F6=1,M6,-1)-ROW()/1000000
A7: ='Sprzedaż'!A7 | B7: ='Sprzedaż'!B7 | C7: =IF(COUNT('Sprzedaż'!C7:N7)=0,"BRAK DANYCH",IF(COUNT('Sprzedaż'!C7:N7)<12,"niepełne","komplet")) | D7: =COUNTIF('Sprzedaż'!C7:N7,">0.001") | E7: t | F7: 1 | G7: =SUM('Sprzedaż'!C7:E7) | H7: =SUM('Sprzedaż'!F7:H7) | I7: =SUM('Sprzedaż'!I7:K7) | J7: =SUM('Sprzedaż'!L7:N7) | K7: =G7+H7 | L7: =I7+J7 | M7: =SUM('Sprzedaż'!C7:N7) | N7: =IF(COUNT('Sprzedaż'!C7:N7)=0,0,M7/12) | O7: =MAX('Sprzedaż'!C7:N7) | P7: =MIN('Sprzedaż'!C7:N7) | Q7: =IF(M7<=0,"-",INDEX('Sprzedaż'!$C$4:$N$4,MATCH(O7,'Sprzedaż'!C7:N7,0))) | R7: =IF(M7<=0,0,(H7+I7)/M7) | S7: =IF(F7=0,"-",IFERROR(M7/SUMIFS($M$5:$M$138,$A$5:$A$138,A7,$F$5:$F$138,1),0)) | T7: =M7-N('Sprzedaż'!O7) | U7: =IF(F7=1,M7,-1)-ROW()/1000000
A8: ='Sprzedaż'!A8 | B8: ='Sprzedaż'!B8 | C8: =IF(COUNT('Sprzedaż'!C8:N8)=0,"BRAK DANYCH",IF(COUNT('Sprzedaż'!C8:N8)<12,"niepełne","komplet")) | D8: =COUNTIF('Sprzedaż'!C8:N8,">0.001") | E8: t | F8: 1 | G8: =SUM('Sprzedaż'!C8:E8) | H8: =SUM('Sprzedaż'!F8:H8) | I8: =SUM('Sprzedaż'!I8:K8) | J8: =SUM('Sprzedaż'!L8:N8) | K8: =G8+H8 | L8: =I8+J8 | M8: =SUM('Sprzedaż'!C8:N8) | N8: =IF(COUNT('Sprzedaż'!C8:N8)=0,0,M8/12) | O8: =MAX('Sprzedaż'!C8:N8) | P8: =MIN('Sprzedaż'!C8:N8) | Q8: =IF(M8<=0,"-",INDEX('Sprzedaż'!$C$4:$N$4,MATCH(O8,'Sprzedaż'!C8:N8,0))) | R8: =IF(M8<=0,0,(H8+I8)/M8) | S8: =IF(F8=0,"-",IFERROR(M8/SUMIFS($M$5:$M$138,$A$5:$A$138,A8,$F$5:$F$138,1),0)) | T8: =M8-N('Sprzedaż'!O8) | U8: =IF(F8=1,M8,-1)-ROW()/1000000
A9: ='Sprzedaż'!A9 | B9: ='Sprzedaż'!B9 | C9: =IF(COUNT('Sprzedaż'!C9:N9)=0,"BRAK DANYCH",IF(COUNT('Sprzedaż'!C9:N9)<12,"niepełne","komplet")) | D9: =COUNTIF('Sprzedaż'!C9:N9,">0.001") | E9: t | F9: 1 | G9: =SUM('Sprzedaż'!C9:E9) | H9: =SUM('Sprzedaż'!F9:H9) | I9: =SUM('Sprzedaż'!I9:K9) | J9: =SUM('Sprzedaż'!L9:N9) | K9: =G9+H9 | L9: =I9+J9 | M9: =SUM('Sprzedaż'!C9:N9) | N9: =IF(COUNT('Sprzedaż'!C9:N9)=0,0,M9/12) | O9: =MAX('Sprzedaż'!C9:N9) | P9: =MIN('Sprzedaż'!C9:N9) | Q9: =IF(M9<=0,"-",INDEX('Sprzedaż'!$C$4:$N$4,MATCH(O9,'Sprzedaż'!C9:N9,0))) | R9: =IF(M9<=0,0,(H9+I9)/M9) | S9: =IF(F9=0,"-",IFERROR(M9/SUMIFS($M$5:$M$138,$A$5:$A$138,A9,$F$5:$F$138,1),0)) | T9: =M9-N('Sprzedaż'!O9) | U9: =IF(F9=1,M9,-1)-ROW()/1000000
A10: ='Sprzedaż'!A10 | B10: ='Sprzedaż'!B10 | C10: =IF(COUNT('Sprzedaż'!C10:N10)=0,"BRAK DANYCH",IF(COUNT('Sprzedaż'!C10:N10)<12,"niepełne","komplet")) | D10: =COUNTIF('Sprzedaż'!C10:N10,">0.001") | E10: t | F10: 1 | G10: =SUM('Sprzedaż'!C10:E10) | H10: =SUM('Sprzedaż'!F10:H10) | I10: =SUM('Sprzedaż'!I10:K10) | J10: =SUM('Sprzedaż'!L10:N10) | K10: =G10+H10 | L10: =I10+J10 | M10: =SUM('Sprzedaż'!C10:N10) | N10: =IF(COUNT('Sprzedaż'!C10:N10)=0,0,M10/12) | O10: =MAX('Sprzedaż'!C10:N10) | P10: =MIN('Sprzedaż'!C10:N10) | Q10: =IF(M10<=0,"-",INDEX('Sprzedaż'!$C$4:$N$4,MATCH(O10,'Sprzedaż'!C10:N10,0))) | R10: =IF(M10<=0,0,(H10+I10)/M10) | S10: =IF(F10=0,"-",IFERROR(M10/SUMIFS($M$5:$M$138,$A$5:$A$138,A10,$F$5:$F$138,1),0)) | T10: =M10-N('Sprzedaż'!O10) | U10: =IF(F10=1,M10,-1)-ROW()/1000000
A11: ='Sprzedaż'!A11 | B11: ='Sprzedaż'!B11 | C11: =IF(COUNT('Sprzedaż'!C11:N11)=0,"BRAK DANYCH",IF(COUNT('Sprzedaż'!C11:N11)<12,"niepełne","komplet")) | D11: =COUNTIF('Sprzedaż'!C11:N11,">0.001") | E11: t | F11: 1 | G11: =SUM('Sprzedaż'!C11:E11) | H11: =SUM('Sprzedaż'!F11:H11) | I11: =SUM('Sprzedaż'!I11:K11) | J11: =SUM('Sprzedaż'!L11:N11) | K11: =G11+H11 | L11: =I11+J11 | M11: =SUM('Sprzedaż'!C11:N11) | N11: =IF(COUNT('Sprzedaż'!C11:N11)=0,0,M11/12) | O11: =MAX('Sprzedaż'!C11:N11) | P11: =MIN('Sprzedaż'!C11:N11) | Q11: =IF(M11<=0,"-",INDEX('Sprzedaż'!$C$4:$N$4,MATCH(O11,'Sprzedaż'!C11:N11,0))) | R11: =IF(M11<=0,0,(H11+I11)/M11) | S11: =IF(F11=0,"-",IFERROR(M11/SUMIFS($M$5:$M$138,$A$5:$A$138,A11,$F$5:$F$138,1),0)) | T11: =M11-N('Sprzedaż'!O11) | U11: =IF(F11=1,M11,-1)-ROW()/1000000
A12: ='Sprzedaż'!A12 | B12: ='Sprzedaż'!B12 | C12: =IF(COUNT('Sprzedaż'!C12:N12)=0,"BRAK DANYCH",IF(COUNT('Sprzedaż'!C12:N12)<12,"niepełne","komplet")) | D12: =COUNTIF('Sprzedaż'!C12:N12,">0.001") | E12: t | F12: 1 | G12: =SUM('Sprzedaż'!C12:E12) | H12: =SUM('Sprzedaż'!F12:H12) | I12: =SUM('Sprzedaż'!I12:K12) | J12: =SUM('Sprzedaż'!L12:N12) | K12: =G12+H12 | L12: =I12+J12 | M12: =SUM('Sprzedaż'!C12:N12) | N12: =IF(COUNT('Sprzedaż'!C12:N12)=0,0,M12/12) | O12: =MAX('Sprzedaż'!C12:N12) | P12: =MIN('Sprzedaż'!C12:N12) | Q12: =IF(M12<=0,"-",INDEX('Sprzedaż'!$C$4:$N$4,MATCH(O12,'Sprzedaż'!C12:N12,0))) | R12: =IF(M12<=0,0,(H12+I12)/M12) | S12: =IF(F12=0,"-",IFERROR(M12/SUMIFS($M$5:$M$138,$A$5:$A$138,A12,$F$5:$F$138,1),0)) | T12: =M12-N('Sprzedaż'!O12) | U12: =IF(F12=1,M12,-1)-ROW()/1000000
A13: ='Sprzedaż'!A13 | B13: ='Sprzedaż'!B13 | C13: =IF(COUNT('Sprzedaż'!C13:N13)=0,"BRAK DANYCH",IF(COUNT('Sprzedaż'!C13:N13)<12,"niepełne","komplet")) | D13: =COUNTIF('Sprzedaż'!C13:N13,">0.001") | E13: t | F13: 1 | G13: =SUM('Sprzedaż'!C13:E13) | H13: =SUM('Sprzedaż'!F13:H13) | I13: =SUM('Sprzedaż'!I13:K13) | J13: =SUM('Sprzedaż'!L13:N13) | K13: =G13+H13 | L13: =I13+J13 | M13: =SUM('Sprzedaż'!C13:N13) | N13: =IF(COUNT('Sprzedaż'!C13:N13)=0,0,M13/12) | O13: =MAX('Sprzedaż'!C13:N13) | P13: =MIN('Sprzedaż'!C13:N13) | Q13: =IF(M13<=0,"-",INDEX('Sprzedaż'!$C$4:$N$4,MATCH(O13,'Sprzedaż'!C13:N13,0))) | R13: =IF(M13<=0,0,(H13+I13)/M13) | S13: =IF(F13=0,"-",IFERROR(M13/SUMIFS($M$5:$M$138,$A$5:$A$138,A13,$F$5:$F$138,1),0)) | T13: =M13-N('Sprzedaż'!O13) | U13: =IF(F13=1,M13,-1)-ROW()/1000000
A14: ='Sprzedaż'!A14 | B14: ='Sprzedaż'!B14 | C14: =IF(COUNT('Sprzedaż'!C14:N14)=0,"BRAK DANYCH",IF(COUNT('Sprzedaż'!C14:N14)<12,"niepełne","komplet")) | D14: =COUNTIF('Sprzedaż'!C14:N14,">0.001") | E14: t | F14: 1 | G14: =SUM('Sprzedaż'!C14:E14) | H14: =SUM('Sprzedaż'!F14:H14) | I14: =SUM('Sprzedaż'!I14:K14) | J14: =SUM('Sprzedaż'!L14:N14) | K14: =G14+H14 | L14: =I14+J14 | M14: =SUM('Sprzedaż'!C14:N14) | N14: =IF(COUNT('Sprzedaż'!C14:N14)=0,0,M14/12) | O14: =MAX('Sprzedaż'!C14:N14) | P14: =MIN('Sprzedaż'!C14:N14) | Q14: =IF(M14<=0,"-",INDEX('Sprzedaż'!$C$4:$N$4,MATCH(O14,'Sprzedaż'!C14:N14,0))) | R14: =IF(M14<=0,0,(H14+I14)/M14) | S14: =IF(F14=0,"-",IFERROR(M14/SUMIFS($M$5:$M$138,$A$5:$A$138,A14,$F$5:$F$138,1),0)) | T14: =M14-N('Sprzedaż'!O14) | U14: =IF(F14=1,M14,-1)-ROW()/1000000
A15: ='Sprzedaż'!A15 | B15: ='Sprzedaż'!B15 | C15: =IF(COUNT('Sprzedaż'!C15:N15)=0,"BRAK DANYCH",IF(COUNT('Sprzedaż'!C15:N15)<12,"niepełne","komplet")) | D15: =COUNTIF('Sprzedaż'!C15:N15,">0.001") | E15: t | F15: 1 | G15: =SUM('Sprzedaż'!C15:E15) | H15: =SUM('Sprzedaż'!F15:H15) | I15: =SUM('Sprzedaż'!I15:K15) | J15: =SUM('Sprzedaż'!L15:N15) | K15: =G15+H15 | L15: =I15+J15 | M15: =SUM('Sprzedaż'!C15:N15) | N15: =IF(COUNT('Sprzedaż'!C15:N15)=0,0,M15/12) | O15: =MAX('Sprzedaż'!C15:N15) | P15: =MIN('Sprzedaż'!C15:N15) | Q15: =IF(M15<=0,"-",INDEX('Sprzedaż'!$C$4:$N$4,MATCH(O15,'Sprzedaż'!C15:N15,0))) | R15: =IF(M15<=0,0,(H15+I15)/M15) | S15: =IF(F15=0,"-",IFERROR(M15/SUMIFS($M$5:$M$138,$A$5:$A$138,A15,$F$5:$F$138,1),0)) | T15: =M15-N('Sprzedaż'!O15) | U15: =IF(F15=1,M15,-1)-ROW()/1000000
A16: ='Sprzedaż'!A16 | B16: ='Sprzedaż'!B16 | C16: =IF(COUNT('Sprzedaż'!C16:N16)=0,"BRAK DANYCH",IF(COUNT('Sprzedaż'!C16:N16)<12,"niepełne","komplet")) | D16: =COUNTIF('Sprzedaż'!C16:N16,">0.001") | E16: t | F16: 1 | G16: =SUM('Sprzedaż'!C16:E16) | H16: =SUM('Sprzedaż'!F16:H16) | I16: =SUM('Sprzedaż'!I16:K16) | J16: =SUM('Sprzedaż'!L16:N16) | K16: =G16+H16 | L16: =I16+J16 | M16: =SUM('Sprzedaż'!C16:N16) | N16: =IF(COUNT('Sprzedaż'!C16:N16)=0,0,M16/12) | O16: =MAX('Sprzedaż'!C16:N16) | P16: =MIN('Sprzedaż'!C16:N16) | Q16: =IF(M16<=0,"-",INDEX('Sprzedaż'!$C$4:$N$4,MATCH(O16,'Sprzedaż'!C16:N16,0))) | R16: =IF(M16<=0,0,(H16+I16)/M16) | S16: =IF(F16=0,"-",IFERROR(M16/SUMIFS($M$5:$M$138,$A$5:$A$138,A16,$F$5:$F$138,1),0)) | T16: =M16-N('Sprzedaż'!O16) | U16: =IF(F16=1,M16,-1)-ROW()/1000000
... A138: ='Sprzedaż'!A138 | B138: ='Sprzedaż'!B138 | C138: =IF(COUNT('Sprzedaż'!C138:N138)=0,"BRAK DANYCH",IF(COUNT('Sprzedaż'!C138:N138)<12,"niepełne","komplet")) | D138: =COUNTIF('Sprzedaż'!C138:N138,">0.001") | E138: t | F138: 1 | G138: =SUM('Sprzedaż'!C138:E138) | H138: =SUM('Sprzedaż'!F138:H138) | I138: =SUM('Sprzedaż'!I138:K138) | J138: =SUM('Sprzedaż'!L138:N138) | K138: =G138+H138 | L138: =I138+J138 | M138: =SUM('Sprzedaż'!C138:N138) | N138: =IF(COUNT('Sprzedaż'!C138:N138)=0,0,M138/12) | O138: =MAX('Sprzedaż'!C138:N138) | P138: =MIN('Sprzedaż'!C138:N138) | Q138: =IF(M138<=0,"-",INDEX('Sprzedaż'!$C$4:$N$4,MATCH(O138,'Sprzedaż'!C138:N138,0))) | R138: =IF(M138<=0,0,(H138+I138)/M138) | S138: =IF(F138=0,"-",IFERROR(M138/SUMIFS($M$5:$M$138,$A$5:$A$138,A138,$F$5:$F$138,1),0)) | T138: =M138-N('Sprzedaż'!O138) | U138: =IF(F138=1,M138,-1)-ROW()/1000000

Sheet Podsumowanie
A1: Podsumowanie – wolumen sprzedaży 2027 wg spółek [t]
A2: Suma ton: bez wierszy-sum (PULREA razem, MELAMINA ogółem), bez jednostek innych niż tony (wodór, CO2 butle, powietrze) i bez wodoru OXO – wg kolumny F w arkuszu „Obliczenia”.
A4: Spółka | B4: styczeń | C4: luty | D4: marzec | E4: kwiecień | F4: maj | G4: czerwiec | H4: lipiec | I4: sierpień | J4: wrzesień | K4: październik | L4: listopad | M4: grudzień | N4: Rok | O4: Q1 | P4: Q2 | Q4: Q3 | R4: Q4 | S4: Udział w Grupie | T4: Średnio / mies. | U4: Liczba produktów | V4: w tym bez danych
A5: ZAP | B5: =SUMPRODUCT(('Sprzedaż'!$A$5:$A$138=$A5)*(Obliczenia!$F$5:$F$138=1),'Sprzedaż'!C$5:C$138) | C5: =SUMPRODUCT(('Sprzedaż'!$A$5:$A$138=$A5)*(Obliczenia!$F$5:$F$138=1),'Sprzedaż'!D$5:D$138) | D5: =SUMPRODUCT(('Sprzedaż'!$A$5:$A$138=$A5)*(Obliczenia!$F$5:$F$138=1),'Sprzedaż'!E$5:E$138) | E5: =SUMPRODUCT(('Sprzedaż'!$A$5:$A$138=$A5)*(Obliczenia!$F$5:$F$138=1),'Sprzedaż'!F$5:F$138) | F5: =SUMPRODUCT(('Sprzedaż'!$A$5:$A$138=$A5)*(Obliczenia!$F$5:$F$138=1),'Sprzedaż'!G$5:G$138) | G5: =SUMPRODUCT(('Sprzedaż'!$A$5:$A$138=$A5)*(Obliczenia!$F$5:$F$138=1),'Sprzedaż'!H$5:H$138) | H5: =SUMPRODUCT(('Sprzedaż'!$A$5:$A$138=$A5)*(Obliczenia!$F$5:$F$138=1),'Sprzedaż'!I$5:I$138) | I5: =SUMPRODUCT(('Sprzedaż'!$A$5:$A$138=$A5)*(Obliczenia!$F$5:$F$138=1),'Sprzedaż'!J$5:J$138) | ... M5: =SUMPRODUCT(('Sprzedaż'!$A$5:$A$138=$A5)*(Obliczenia!$F$5:$F$138=1),'Sprzedaż'!N$5:N$138) | N5: =SUM(B5:M5) | O5: =SUM(B5:D5) | P5: =SUM(E5:G5) | Q5: =SUM(H5:J5) | R5: =SUM(K5:M5) | S5: =IF($N$10=0,0,N5/$N$10) | T5: =N5/12 | U5: =SUMPRODUCT(('Sprzedaż'!$A$5:$A$138=$A5)*('Sprzedaż'!$B$5:$B$138<>"")) | V5: =COUNTIFS('Sprzedaż'!$A$5:$A$138,$A5,Obliczenia!$C$5:$C$138,"BRAK DANYCH")
A6: ZAK | B6: =SUMPRODUCT(('Sprzedaż'!$A$5:$A$138=$A6)*(Obliczenia!$F$5:$F$138=1),'Sprzedaż'!C$5:C$138) | C6: =SUMPRODUCT(('Sprzedaż'!$A$5:$A$138=$A6)*(Obliczenia!$F$5:$F$138=1),'Sprzedaż'!D$5:D$138) | D6: =SUMPRODUCT(('Sprzedaż'!$A$5:$A$138=$A6)*(Obliczenia!$F$5:$F$138=1),'Sprzedaż'!E$5:E$138) | E6: =SUMPRODUCT(('Sprzedaż'!$A$5:$A$138=$A6)*(Obliczenia!$F$5:$F$138=1),'Sprzedaż'!F$5:F$138) | F6: =SUMPRODUCT(('Sprzedaż'!$A$5:$A$138=$A6)*(Obliczenia!$F$5:$F$138=1),'Sprzedaż'!G$5:G$138) | G6: =SUMPRODUCT(('Sprzedaż'!$A$5:$A$138=$A6)*(Obliczenia!$F$5:$F$138=1),'Sprzedaż'!H$5:H$138) | H6: =SUMPRODUCT(('Sprzedaż'!$A$5:$A$138=$A6)*(Obliczenia!$F$5:$F$138=1),'Sprzedaż'!I$5:I$138) | I6: =SUMPRODUCT(('Sprzedaż'!$A$5:$A$138=$A6)*(Obliczenia!$F$5:$F$138=1),'Sprzedaż'!J$5:J$138) | ... M6: =SUMPRODUCT(('Sprzedaż'!$A$5:$A$138=$A6)*(Obliczenia!$F$5:$F$138=1),'Sprzedaż'!N$5:N$138) | N6: =SUM(B6:M6) | O6: =SUM(B6:D6) | P6: =SUM(E6:G6) | Q6: =SUM(H6:J6) | R6: =SUM(K6:M6) | S6: =IF($N$10=0,0,N6/$N$10) | T6: =N6/12 | U6: =SUMPRODUCT(('Sprzedaż'!$A$5:$A$138=$A6)*('Sprzedaż'!$B$5:$B$138<>"")) | V6: =COUNTIFS('Sprzedaż'!$A$5:$A$138,$A6,Obliczenia!$C$5:$C$138,"BRAK DANYCH")
A7: ZAT | B7: =SUMPRODUCT(('Sprzedaż'!$A$5:$A$138=$A7)*(Obliczenia!$F$5:$F$138=1),'Sprzedaż'!C$5:C$138) | C7: =SUMPRODUCT(('Sprzedaż'!$A$5:$A$138=$A7)*(Obliczenia!$F$5:$F$138=1),'Sprzedaż'!D$5:D$138) | D7: =SUMPRODUCT(('Sprzedaż'!$A$5:$A$138=$A7)*(Obliczenia!$F$5:$F$138=1),'Sprzedaż'!E$5:E$138) | E7: =SUMPRODUCT(('Sprzedaż'!$A$5:$A$138=$A7)*(Obliczenia!$F$5:$F$138=1),'Sprzedaż'!F$5:F$138) | F7: =SUMPRODUCT(('Sprzedaż'!$A$5:$A$138=$A7)*(Obliczenia!$F$5:$F$138=1),'Sprzedaż'!G$5:G$138) | G7: =SUMPRODUCT(('Sprzedaż'!$A$5:$A$138=$A7)*(Obliczenia!$F$5:$F$138=1),'Sprzedaż'!H$5:H$138) | H7: =SUMPRODUCT(('Sprzedaż'!$A$5:$A$138=$A7)*(Obliczenia!$F$5:$F$138=1),'Sprzedaż'!I$5:I$138) | I7: =SUMPRODUCT(('Sprzedaż'!$A$5:$A$138=$A7)*(Obliczenia!$F$5:$F$138=1),'Sprzedaż'!J$5:J$138) | ... M7: =SUMPRODUCT(('Sprzedaż'!$A$5:$A$138=$A7)*(Obliczenia!$F$5:$F$138=1),'Sprzedaż'!N$5:N$138) | N7: =SUM(B7:M7) | O7: =SUM(B7:D7) | P7: =SUM(E7:G7) | Q7: =SUM(H7:J7) | R7: =SUM(K7:M7) | S7: =IF($N$10=0,0,N7/$N$10) | T7: =N7/12 | U7: =SUMPRODUCT(('Sprzedaż'!$A$5:$A$138=$A7)*('Sprzedaż'!$B$5:$B$138<>"")) | V7: =COUNTIFS('Sprzedaż'!$A$5:$A$138,$A7,Obliczenia!$C$5:$C$138,"BRAK DANYCH")
A8: ZChP | B8: =SUMPRODUCT(('Sprzedaż'!$A$5:$A$138=$A8)*(Obliczenia!$F$5:$F$138=1),'Sprzedaż'!C$5:C$138) | C8: =SUMPRODUCT(('Sprzedaż'!$A$5:$A$138=$A8)*(Obliczenia!$F$5:$F$138=1),'Sprzedaż'!D$5:D$138) | D8: =SUMPRODUCT(('Sprzedaż'!$A$5:$A$138=$A8)*(Obliczenia!$F$5:$F$138=1),'Sprzedaż'!E$5:E$138) | E8: =SUMPRODUCT(('Sprzedaż'!$A$5:$A$138=$A8)*(Obliczenia!$F$5:$F$138=1),'Sprzedaż'!F$5:F$138) | F8: =SUMPRODUCT(('Sprzedaż'!$A$5:$A$138=$A8)*(Obliczenia!$F$5:$F$138=1),'Sprzedaż'!G$5:G$138) | G8: =SUMPRODUCT(('Sprzedaż'!$A$5:$A$138=$A8)*(Obliczenia!$F$5:$F$138=1),'Sprzedaż'!H$5:H$138) | H8: =SUMPRODUCT(('Sprzedaż'!$A$5:$A$138=$A8)*(Obliczenia!$F$5:$F$138=1),'Sprzedaż'!I$5:I$138) | I8: =SUMPRODUCT(('Sprzedaż'!$A$5:$A$138=$A8)*(Obliczenia!$F$5:$F$138=1),'Sprzedaż'!J$5:J$138) | ... M8: =SUMPRODUCT(('Sprzedaż'!$A$5:$A$138=$A8)*(Obliczenia!$F$5:$F$138=1),'Sprzedaż'!N$5:N$138) | N8: =SUM(B8:M8) | O8: =SUM(B8:D8) | P8: =SUM(E8:G8) | Q8: =SUM(H8:J8) | R8: =SUM(K8:M8) | S8: =IF($N$10=0,0,N8/$N$10) | T8: =N8/12 | U8: =SUMPRODUCT(('Sprzedaż'!$A$5:$A$138=$A8)*('Sprzedaż'!$B$5:$B$138<>"")) | V8: =COUNTIFS('Sprzedaż'!$A$5:$A$138,$A8,Obliczenia!$C$5:$C$138,"BRAK DANYCH")
A9: Fosfory | B9: =SUMPRODUCT(('Sprzedaż'!$A$5:$A$138=$A9)*(Obliczenia!$F$5:$F$138=1),'Sprzedaż'!C$5:C$138) | C9: =SUMPRODUCT(('Sprzedaż'!$A$5:$A$138=$A9)*(Obliczenia!$F$5:$F$138=1),'Sprzedaż'!D$5:D$138) | D9: =SUMPRODUCT(('Sprzedaż'!$A$5:$A$138=$A9)*(Obliczenia!$F$5:$F$138=1),'Sprzedaż'!E$5:E$138) | E9: =SUMPRODUCT(('Sprzedaż'!$A$5:$A$138=$A9)*(Obliczenia!$F$5:$F$138=1),'Sprzedaż'!F$5:F$138) | F9: =SUMPRODUCT(('Sprzedaż'!$A$5:$A$138=$A9)*(Obliczenia!$F$5:$F$138=1),'Sprzedaż'!G$5:G$138) | G9: =SUMPRODUCT(('Sprzedaż'!$A$5:$A$138=$A9)*(Obliczenia!$F$5:$F$138=1),'Sprzedaż'!H$5:H$138) | H9: =SUMPRODUCT(('Sprzedaż'!$A$5:$A$138=$A9)*(Obliczenia!$F$5:$F$138=1),'Sprzedaż'!I$5:I$138) | I9: =SUMPRODUCT(('Sprzedaż'!$A$5:$A$138=$A9)*(Obliczenia!$F$5:$F$138=1),'Sprzedaż'!J$5:J$138) | ... M9: =SUMPRODUCT(('Sprzedaż'!$A$5:$A$138=$A9)*(Obliczenia!$F$5:$F$138=1),'Sprzedaż'!N$5:N$138) | N9: =SUM(B9:M9) | O9: =SUM(B9:D9) | P9: =SUM(E9:G9) | Q9: =SUM(H9:J9) | R9: =SUM(K9:M9) | S9: =IF($N$10=0,0,N9/$N$10) | T9: =N9/12 | U9: =SUMPRODUCT(('Sprzedaż'!$A$5:$A$138=$A9)*('Sprzedaż'!$B$5:$B$138<>"")) | V9: =COUNTIFS('Sprzedaż'!$A$5:$A$138,$A9,Obliczenia!$C$5:$C$138,"BRAK DANYCH")
A10: GRUPA razem | B10: =SUM(B5:B9) | C10: =SUM(C5:C9) | D10: =SUM(D5:D9) | E10: =SUM(E5:E9) | F10: =SUM(F5:F9) | G10: =SUM(G5:G9) | H10: =SUM(H5:H9) | I10: =SUM(I5:I9) | ... V10: =SUM(V5:V9)
A11: Udział miesiąca w roku | B11: =IF($N$10=0,0,B10/$N$10) | C11: =IF($N$10=0,0,C10/$N$10) | D11: =IF($N$10=0,0,D10/$N$10) | E11: =IF($N$10=0,0,E10/$N$10) | F11: =IF($N$10=0,0,F10/$N$10) | G11: =IF($N$10=0,0,G10/$N$10) | H11: =IF($N$10=0,0,H10/$N$10) | I11: =IF($N$10=0,0,I10/$N$10) | ... R11: =IF($N$10=0,0,R10/$N$10)
A13: Produkty w innych jednostkach (poza sumą ton)
A14: Spółka | B14: Produkt | C14: styczeń | D14: luty | E14: marzec | F14: kwiecień | G14: maj | H14: czerwiec | I14: lipiec | J14: sierpień | K14: wrzesień | L14: październik | M14: listopad | N14: grudzień | O14: Rok | P14: Jednostka
A15: ='Sprzedaż'!A6 | B15: ='Sprzedaż'!B6 | C15: ='Sprzedaż'!C6 | D15: ='Sprzedaż'!D6 | E15: ='Sprzedaż'!E6 | F15: ='Sprzedaż'!F6 | G15: ='Sprzedaż'!G6 | H15: ='Sprzedaż'!H6 | ... N15: ='Sprzedaż'!N6 | O15: =SUM(C15:N15) | P15: =Obliczenia!E6
A16: ='Sprzedaż'!A38 | B16: ='Sprzedaż'!B38 | C16: ='Sprzedaż'!C38 | D16: ='Sprzedaż'!D38 | E16: ='Sprzedaż'!E38 | F16: ='Sprzedaż'!F38 | G16: ='Sprzedaż'!G38 | H16: ='Sprzedaż'!H38 | ... N16: ='Sprzedaż'!N38 | O16: =SUM(C16:N16) | P16: =Obliczenia!E38
A17: ='Sprzedaż'!A39 | B17: ='Sprzedaż'!B39 | C17: ='Sprzedaż'!C39 | D17: ='Sprzedaż'!D39 | E17: ='Sprzedaż'!E39 | F17: ='Sprzedaż'!F39 | G17: ='Sprzedaż'!G39 | H17: ='Sprzedaż'!H39 | ... N17: ='Sprzedaż'!N39 | O17: =SUM(C17:N17) | P17: =Obliczenia!E39
A18: ='Sprzedaż'!A56 | B18: ='Sprzedaż'!B56 | C18: ='Sprzedaż'!C56 | D18: ='Sprzedaż'!D56 | E18: ='Sprzedaż'!E56 | F18: ='Sprzedaż'!F56 | G18: ='Sprzedaż'!G56 | H18: ='Sprzedaż'!H56 | ... N18: ='Sprzedaż'!N56 | O18: =SUM(C18:N18) | P18: =Obliczenia!E56
A19: ='Sprzedaż'!A57 | B19: ='Sprzedaż'!B57 | C19: ='Sprzedaż'!C57 | D19: ='Sprzedaż'!D57 | E19: ='Sprzedaż'!E57 | F19: ='Sprzedaż'!F57 | G19: ='Sprzedaż'!G57 | H19: ='Sprzedaż'!H57 | ... N19: ='Sprzedaż'!N57 | O19: =SUM(C19:N19) | P19: =Obliczenia!E57
A22: TOP 10 produktów wg wolumenu rocznego [t]
A23: Miejsce | B23: Produkt | C23: Spółka | D23: Rok [t] | E23: Udział w Grupie
A24: 1 | B24: =INDEX(Obliczenia!$B$5:$B$138,MATCH(LARGE(Obliczenia!$U$5:$U$138,1),Obliczenia!$U$5:$U$138,0)) | C24: =INDEX(Obliczenia!$A$5:$A$138,MATCH(LARGE(Obliczenia!$U$5:$U$138,1),Obliczenia!$U$5:$U$138,0)) | D24: =INDEX(Obliczenia!$M$5:$M$138,MATCH(LARGE(Obliczenia!$U$5:$U$138,1),Obliczenia!$U$5:$U$138,0)) | E24: =IF($N$10=0,0,D24/$N$10)
A25: 2 | B25: =INDEX(Obliczenia!$B$5:$B$138,MATCH(LARGE(Obliczenia!$U$5:$U$138,2),Obliczenia!$U$5:$U$138,0)) | C25: =INDEX(Obliczenia!$A$5:$A$138,MATCH(LARGE(Obliczenia!$U$5:$U$138,2),Obliczenia!$U$5:$U$138,0)) | D25: =INDEX(Obliczenia!$M$5:$M$138,MATCH(LARGE(Obliczenia!$U$5:$U$138,2),Obliczenia!$U$5:$U$138,0)) | E25: =IF($N$10=0,0,D25/$N$10)
A26: 3 | B26: =INDEX(Obliczenia!$B$5:$B$138,MATCH(LARGE(Obliczenia!$U$5:$U$138,3),Obliczenia!$U$5:$U$138,0)) | C26: =INDEX(Obliczenia!$A$5:$A$138,MATCH(LARGE(Obliczenia!$U$5:$U$138,3),Obliczenia!$U$5:$U$138,0)) | D26: =INDEX(Obliczenia!$M$5:$M$138,MATCH(LARGE(Obliczenia!$U$5:$U$138,3),Obliczenia!$U$5:$U$138,0)) | E26: =IF($N$10=0,0,D26/$N$10)
A27: 4 | B27: =INDEX(Obliczenia!$B$5:$B$138,MATCH(LARGE(Obliczenia!$U$5:$U$138,4),Obliczenia!$U$5:$U$138,0)) | C27: =INDEX(Obliczenia!$A$5:$A$138,MATCH(LARGE(Obliczenia!$U$5:$U$138,4),Obliczenia!$U$5:$U$138,0)) | D27: =INDEX(Obliczenia!$M$5:$M$138,MATCH(LARGE(Obliczenia!$U$5:$U$138,4),Obliczenia!$U$5:$U$138,0)) | E27: =IF($N$10=0,0,D27/$N$10)
A28: 5 | B28: =INDEX(Obliczenia!$B$5:$B$138,MATCH(LARGE(Obliczenia!$U$5:$U$138,5),Obliczenia!$U$5:$U$138,0)) | C28: =INDEX(Obliczenia!$A$5:$A$138,MATCH(LARGE(Obliczenia!$U$5:$U$138,5),Obliczenia!$U$5:$U$138,0)) | D28: =INDEX(Obliczenia!$M$5:$M$138,MATCH(LARGE(Obliczenia!$U$5:$U$138,5),Obliczenia!$U$5:$U$138,0)) | E28: =IF($N$10=0,0,D28/$N$10)
A29: 6 | B29: =INDEX(Obliczenia!$B$5:$B$138,MATCH(LARGE(Obliczenia!$U$5:$U$138,6),Obliczenia!$U$5:$U$138,0)) | C29: =INDEX(Obliczenia!$A$5:$A$138,MATCH(LARGE(Obliczenia!$U$5:$U$138,6),Obliczenia!$U$5:$U$138,0)) | D29: =INDEX(Obliczenia!$M$5:$M$138,MATCH(LARGE(Obliczenia!$U$5:$U$138,6),Obliczenia!$U$5:$U$138,0)) | E29: =IF($N$10=0,0,D29/$N$10)
A30: 7 | B30: =INDEX(Obliczenia!$B$5:$B$138,MATCH(LARGE(Obliczenia!$U$5:$U$138,7),Obliczenia!$U$5:$U$138,0)) | C30: =INDEX(Obliczenia!$A$5:$A$138,MATCH(LARGE(Obliczenia!$U$5:$U$138,7),Obliczenia!$U$5:$U$138,0)) | D30: =INDEX(Obliczenia!$M$5:$M$138,MATCH(LARGE(Obliczenia!$U$5:$U$138,7),Obliczenia!$U$5:$U$138,0)) | E30: =IF($N$10=0,0,D30/$N$10)
A31: 8 | B31: =INDEX(Obliczenia!$B$5:$B$138,MATCH(LARGE(Obliczenia!$U$5:$U$138,8),Obliczenia!$U$5:$U$138,0)) | C31: =INDEX(Obliczenia!$A$5:$A$138,MATCH(LARGE(Obliczenia!$U$5:$U$138,8),Obliczenia!$U$5:$U$138,0)) | D31: =INDEX(Obliczenia!$M$5:$M$138,MATCH(LARGE(Obliczenia!$U$5:$U$138,8),Obliczenia!$U$5:$U$138,0)) | E31: =IF($N$10=0,0,D31/$N$10)
A32: 9 | B32: =INDEX(Obliczenia!$B$5:$B$138,MATCH(LARGE(Obliczenia!$U$5:$U$138,9),Obliczenia!$U$5:$U$138,0)) | C32: =INDEX(Obliczenia!$A$5:$A$138,MATCH(LARGE(Obliczenia!$U$5:$U$138,9),Obliczenia!$U$5:$U$138,0)) | D32: =INDEX(Obliczenia!$M$5:$M$138,MATCH(LARGE(Obliczenia!$U$5:$U$138,9),Obliczenia!$U$5:$U$138,0)) | E32: =IF($N$10=0,0,D32/$N$10)
A33: 10 | B33: =INDEX(Obliczenia!$B$5:$B$138,MATCH(LARGE(Obliczenia!$U$5:$U$138,10),Obliczenia!$U$5:$U$138,0)) | C33: =INDEX(Obliczenia!$A$5:$A$138,MATCH(LARGE(Obliczenia!$U$5:$U$138,10),Obliczenia!$U$5:$U$138,0)) | D33: =INDEX(Obliczenia!$M$5:$M$138,MATCH(LARGE(Obliczenia!$U$5:$U$138,10),Obliczenia!$U$5:$U$138,0)) | E33: =IF($N$10=0,0,D33/$N$10)

Sheet Kontrola
A1: Kontrola kompletności i spójności danych od sprzedaży
A3: Kontrola | B3: Wynik | C3: Status | D3: Opis
A4: Produkty bez żadnych danych | B4: =COUNTIF(Obliczenia!$C$5:$C$138,"BRAK DANYCH") | C4: =IF(B4=0,"OK","DO UZUPEŁNIENIA") | D4: Wiersze, w których sprzedaż nie podała wolumenu – lista poniżej. Puste = brak planu albo brak odpowiedzi; potwierdzić ze sprzedażą.
A5: Produkty z niepełnym rokiem | B5: =COUNTIF(Obliczenia!$C$5:$C$138,"niepełne") | C5: =IF(B5=0,"OK","SPRAWDŹ") | D5: Część miesięcy pusta (np. sprzedaż kampanijna). Jeśli ma być 0 – warto wpisać 0, żeby odróżnić od braku danych.
A6: Rozbieżności ∑ roku vs kolumna O | B6: =SUMPRODUCT(--(ABS(Obliczenia!$T$5:$T$138)>0.5)) | C6: =IF(B6=0,"OK","BŁĄD") | D6: Porównanie sumy 12 miesięcy z kolumną ∑ w arkuszu Sprzedaż.
A7: PULREA razem = chemia + agro | B7: =SUMPRODUCT(ABS('Sprzedaż'!C18:N18-'Sprzedaż'!C16:N16-'Sprzedaż'!C17:N17)) | C7: =IF(B7<0.5,"OK","BŁĄD") | D7: Wiersz 18 musi być sumą wierszy 16 i 17.
A8: MELAMINA ogółem = I + II + III | B8: =SUMPRODUCT(ABS('Sprzedaż'!C26:N26-'Sprzedaż'!C27:N27-'Sprzedaż'!C28:N28-'Sprzedaż'!C29:N29)) | C8: =IF(B8<0.5,"OK","BŁĄD") | D8: Wiersz 26 uzupełniono formułą sumy wierszy 27–29.
A9: Wartości ujemne | B9: =COUNTIF('Sprzedaż'!C5:N138,"<0") | C9: =IF(B9=0,"OK","BŁĄD") | D9: Wolumen sprzedaży nie może być ujemny.
A10: Ułamkowe resztki (< 0,001 t) | B10: =SUMPRODUCT(('Sprzedaż'!C5:N138>0)*('Sprzedaż'!C5:N138<0.001)) | C10: =IF(B10=0,"OK","INFO") | D10: ZAK: SALMAG z siarką / z borem mają w pustych miesiącach wartości rzędu 1E-188 z pliku źródłowego – w praktyce 0.
A11: Suma ton Grupy (rok) | B11: =Podsumowanie!N10 | C11: ="INFO" | D11: Z arkusza Podsumowanie.
A13: Wiersze do potwierdzenia ze sprzedażą
A14: Spółka | B14: Produkt | C14: Status | D14: Wiersz w arkuszu Sprzedaż
A15: ='Sprzedaż'!A11 | B15: ='Sprzedaż'!B11 | C15: =Obliczenia!C11 | D15: 11
A16: ='Sprzedaż'!A19 | B16: ='Sprzedaż'!B19 | C16: =Obliczenia!C19 | D16: 19
A17: ='Sprzedaż'!A20 | B17: ='Sprzedaż'!B20 | C17: =Obliczenia!C20 | D17: 20
A18: ='Sprzedaż'!A21 | B18: ='Sprzedaż'!B21 | C18: =Obliczenia!C21 | D18: 21
A19: ='Sprzedaż'!A22 | B19: ='Sprzedaż'!B22 | C19: =Obliczenia!C22 | D19: 22
A20: ='Sprzedaż'!A23 | B20: ='Sprzedaż'!B23 | C20: =Obliczenia!C23 | D20: 23
A21: ='Sprzedaż'!A27 | B21: ='Sprzedaż'!B27 | C21: =Obliczenia!C27 | D21: 27
A22: ='Sprzedaż'!A28 | B22: ='Sprzedaż'!B28 | C22: =Obliczenia!C28 | D22: 28
A23: ='Sprzedaż'!A29 | B23: ='Sprzedaż'!B29 | C23: =Obliczenia!C29 | D23: 29
A24: ='Sprzedaż'!A30 | B24: ='Sprzedaż'!B30 | C24: =Obliczenia!C30 | D24: 30
A25: ='Sprzedaż'!A31 | B25: ='Sprzedaż'!B31 | C25: =Obliczenia!C31 | D25: 31
A26: ='Sprzedaż'!A69 | B26: ='Sprzedaż'!B69 | C26: =Obliczenia!C69 | D26: 69
A27: ='Sprzedaż'!A71 | B27: ='Sprzedaż'!B71 | C27: =Obliczenia!C71 | D27: 71
A28: ='Sprzedaż'!A72 | B28: ='Sprzedaż'!B72 | C28: =Obliczenia!C72 | D28: 72
A29: ='Sprzedaż'!A76 | B29: ='Sprzedaż'!B76 | C29: =Obliczenia!C76 | D29: 76
A30: ='Sprzedaż'!A90 | B30: ='Sprzedaż'!B90 | C30: =Obliczenia!C90 | D30: 90
A31: ='Sprzedaż'!A91 | B31: ='Sprzedaż'!B91 | C31: =Obliczenia!C91 | D31: 91
A32: ='Sprzedaż'!A92 | B32: ='Sprzedaż'!B92 | C32: =Obliczenia!C92 | D32: 92
A33: ='Sprzedaż'!A103 | B33: ='Sprzedaż'!B103 | C33: =Obliczenia!C103 | D33: 103
A34: ='Sprzedaż'!A108 | B34: ='Sprzedaż'!B108 | C34: =Obliczenia!C108 | D34: 108
A35: ='Sprzedaż'!A109 | B35: ='Sprzedaż'!B109 | C35: =Obliczenia!C109 | D35: 109
A36: ='Sprzedaż'!A110 | B36: ='Sprzedaż'!B110 | C36: =Obliczenia!C110 | D36: 110
A37: ='Sprzedaż'!A111 | B37: ='Sprzedaż'!B111 | C37: =Obliczenia!C111 | D37: 111
A38: ='Sprzedaż'!A112 | B38: ='Sprzedaż'!B112 | C38: =Obliczenia!C112 | D38: 112
A39: ='Sprzedaż'!A113 | B39: ='Sprzedaż'!B113 | C39: =Obliczenia!C113 | D39: 113
A40: ='Sprzedaż'!A114 | B40: ='Sprzedaż'!B114 | C40: =Obliczenia!C114 | D40: 114
A41: ='Sprzedaż'!A115 | B41: ='Sprzedaż'!B115 | C41: =Obliczenia!C115 | D41: 115
A42: ='Sprzedaż'!A116 | B42: ='Sprzedaż'!B116 | C42: =Obliczenia!C116 | D42: 116
...
