Workbook

Sheet Instrukcja
B2: Przegląd Decyzji · karta analizy
B3: Narzędzie prowadzącej. Jeden plik = jeden klient. Zapisz kopię jako „Nazwa klienta_data.xlsx”.
B5: 1. Klient | C5: Dane z karty przygotowania i kalkulatora klienta (arkusz Podsumowanie).
B6: 2. Analiza | C6: Przed sesją: dla 3 decyzji oceń 6 ogniw (1–5), wpisz ukryte założenia, sygnały ostrzegawcze, pytania i hipotezę. Arkusz wskaże najsłabsze ogniwo i kolejność omawiania.
B7: 3. Sesja | C7: Pracuj według scenariusza 120 min (Pakiet prowadzącej, rozdz. 6). Po sesji uzupełnij werdykty, zmiany i wzorzec decyzyjny.
B8: 4. Raport | C8: Arkusz Raport składa się sam. Uzupełnij pola brzoskwiniowe (podsumowanie, rekomendacje, plan 30 dni), potem Plik → Drukuj → PDF i wyślij klientowi w 3 dni robocze.
B9: Skala ogniw | C9: 1–2 słabe · 3 wystarczające · 4–5 mocne (kryteria: Pakiet prowadzącej, rozdz. 5).
B10: Przykład | C10: Plik zawiera przykładowe dane fikcyjnego klienta „Studio Lumen”. Usuń je przed pierwszym użyciem.

Sheet Klient
B2: Klient
B3: Dane z karty przygotowania do konsultacji
B5: Klient (osoba) | C5: Anna Nowak (przykład)
B6: Firma | C6: Studio Lumen (fikcyjne)
B7: Branża / liczba osób | C7: Studio graficzno-marketingowe, 6 osób
B8: Data sesji | C8: 2026-11-20
B9: Przychód / marża netto (12 mies.) | C9: 1,2 mln zł / 8%
B10: Wynik audytu / najsłabszy obszar | C10: 31/60 · Oferta i ceny
B11: Cel na 12 miesięcy | C11: Marża netto 18%, 40% przychodu z abonamentów
B12: Czego oczekuje po konsultacji | C12: Pewności, że podwyżka nie zniszczy relacji z największymi klientami
B13: Decyzja z najmniejszą pewnością | C13: Podwyżka 10% dla wszystkich obecnych klientów
B14: Inni decydenci | C14: Wspólnik (udziały 30%), nie uczestniczył w programie

Sheet Analiza
B2: Analiza toku rozumowania
B3: Wiersze = elementy analizy, kolumny = decyzje. Brzoskwiniowe pola wypełniasz.
C5: Decyzja 1 | D5: Decyzja 2 | E5: Decyzja 3
B6: Decyzja (z karty klienta) | C6: Gdzie grać: kliniki i gabinety + pakiet flagowy | D6: Ceny: podwyżka 10% dla wszystkich od 1.03 | E6: 3 priorytety: abonament, cennik, standard sprzedaży
B8: OCENA 6 OGNIW (1–5)
B9: Rama | C9: 4 | D9: 3 | E9: 3
B10: Opcje | C10: 2 | D10: 1 | E10: 3
B11: Informacje | C11: 4 | D11: 3 | E11: 2
B12: Kryteria | C12: 3 | D12: 2 | E12: 3
B13: Rozumowanie | C13: 3 | D13: 2 | E13: 3
B14: Zobowiązanie | C14: 3 | D14: 4 | E14: 2
B15: Średnia | C15: =IFERROR(ROUND(AVERAGE(C9:C14),1),"") | D15: =IFERROR(ROUND(AVERAGE(D9:D14),1),"") | E15: =IFERROR(ROUND(AVERAGE(E9:E14),1),"")
B16: Najsłabsze ogniwo | C16: =IFERROR(INDEX($B$9:$B$14,MATCH(MIN(C9:C14),C9:C14,0))&" ("&MIN(C9:C14)&")","") | D16: =IFERROR(INDEX($B$9:$B$14,MATCH(MIN(D9:D14),D9:D14,0))&" ("&MIN(D9:D14)&")","") | E16: =IFERROR(INDEX($B$9:$B$14,MATCH(MIN(E9:E14),E9:E14,0))&" ("&MIN(E9:E14)&")","")
B17: Kolejność omawiania (1 = najpierw) | C17: =IFERROR(RANK(C15,$C$15:$E$15,1),"") | D17: =IFERROR(RANK(D15,$C$15:$E$15,1),"") | E17: =IFERROR(RANK(E15,$C$15:$E$15,1),"")
B19: NOTATKI DO OGNIW (dlaczego taka ocena)
B20: Mocne strony | C20: Dane z kalkulatora potwierdzają: najwyższy zysk/h w medycznych | D20: Jedna opcja: +10% dla wszystkich; brak wariantu dla Gwiazd | E20: Lista pomysłów obszerna, wybór sensowny
B21: Luki w informacjach | C21: Tylko 2 rozmowy z klientami z segmentu | D21: Brak danych o elastyczności: klient A (18% przychodu) bez rozmowy | E21: Brak oszacowania czasu wdrożenia
B22: Zobowiązanie / wdrożenie | C22: Pre-mortem konkretny | D22: Pre-mortem: „nic nie pójdzie źle” | E22: Trzy priorytety wymagają pracy właścicielki
B24: UKRYTE ZAŁOŻENIA (klient ich nie zapisał)
B25: Założenie 1 | C25: Gabinety mają budżet na pakiet 16 900 zł | D25: Klient A nie ma alternatywy w tej cenie | E25: Właścicielka znajdzie 6 h tygodniowo
B26: Założenie 2 | C26: Partner (biura rachunkowe) poleca aktywnie | D26: Wszyscy klienci reagują na podwyżkę tak samo | E26: PM przejmie rozmowy bez szkolenia
B27: Założenie 3 | D27: Wspólnik zaakceptuje ryzyko utraty klienta A
B29: SYGNAŁY OSTRZEGAWCZE (wpisz X)
B30: Jedna opcja jako jedyna możliwa | D30: X
B31: „Wszyscy w branży tak robią” | D31: X
B32: Cena względem konkurencji / dawnego cennika
B33: Decyzja chroni przed stratą, nie buduje zysku | D33: X
B34: Cel bez liczby lub terminu
B35: Pewność 90%+ przy słabych danych | D35: X
B36: Każda decyzja wymaga pracy właściciela | E36: X
B37: Pre-mortem pusty | D37: X
B38: Trzymanie nierentownego klienta z sentymentu
B39: Wdrożenie „przy okazji” | E39: X
B40: Liczba sygnałów | C40: =COUNTIF(C30:C39,"X") | D40: =COUNTIF(D30:D39,"X") | E40: =COUNTIF(E30:E39,"X")
B42: PYTANIA NA SESJĘ
B43: Pytanie 1 | C43: Co musiałoby być prawdą, żeby gabinety kupowały pakiet za 16 900 zł? | D43: Co by Pani zrobiła, gdyby podwyżka dla klienta A była niemożliwa? | E43: Co Pani przestanie robić, żeby znaleźć 6 h tygodniowo?
B44: Pytanie 2 | C44: Który segment odrzuciła Pani najszybciej i dlaczego? | D44: Czego najbardziej się Pani obawia w rozmowie z klientem A? | E44: Kto poza Panią może prowadzić rozmowy o abonamencie?
B45: Pytanie 3 | C45: Jaki fakt zmieniłby Pani zdanie co do segmentu? | D45: Co doradziłaby Pani znajomej właścicielce w tej sytuacji? | E45: Po czym pozna Pani w 4. tygodniu, że plan nie działa?
B47: HIPOTEZA PRZED SESJĄ
B48: Moja hipoteza (zostaw / popraw / wstrzymaj + dlaczego) | C48: Zostaw. Mocne dane; dodać test z 5 gabinetami | D48: Popraw. Zróżnicować podwyżkę: Gwiazdy +5% z wartością dodaną, „Do pożegnania” +15%, klient A rozmowa osobista | E48: Popraw. Odciążyć właścicielkę: standard sprzedaży jako priorytet 1
...

Sheet Raport
B2: Raport z konsultacji Przegląd Decyzji
B3: guliwera4.pl · poufne
B4: =Klient!C6&" · "&Klient!C5 | F4: ="Data sesji: "&Klient!C8
B6: 1. PODSUMOWANIE
B7: Firma ma mocny fundament: wybrany segment medyczny daje najwyższy zysk na godzinę, a dane z kalkulatora go potwierdzają. Najsłabszym miejscem planu jest decyzja o cenach: oparta na jednej opcji i na obawie przed utratą klienta A, a nie na jego realnej sytuacji. Plan wymaga też odciążenia właścicielki, żeby był wykonalny.
B9: 2. MAPA DECYZJI
B10: Decyzja | C10: Średnia ocena (1–5) | D10: Najsłabsze ogniwo | E10: Werdykt | F10: Co zmieniamy
B11: =Analiza!C6 | C11: =Analiza!C15 | D11: =Analiza!C16 | E11: =Analiza!C51 | F11: =Analiza!C52
B12: =Analiza!D6 | C12: =Analiza!D15 | D12: =Analiza!D16 | E12: =Analiza!D51 | F12: =Analiza!D52
B13: =Analiza!E6 | C13: =Analiza!E15 | D13: =Analiza!E16 | E13: =Analiza!E51 | F13: =Analiza!E52
B15: 3. OCENA 6 OGNIW
B16: Ogniwo | C16: Decyzja 1 | D16: Decyzja 2 | E16: Decyzja 3
B17: Rama | C17: =Analiza!C9 | D17: =Analiza!D9 | E17: =Analiza!E9 | F17: Skala: 1–2 słabe · 3 wystarczające · 4–5 mocne. Decyzja jest tak mocna, jak jej najsłabsze ogniwo.
B18: Opcje | C18: =Analiza!C10 | D18: =Analiza!D10 | E18: =Analiza!E10
B19: Informacje | C19: =Analiza!C11 | D19: =Analiza!D11 | E19: =Analiza!E11
B20: Kryteria | C20: =Analiza!C12 | D20: =Analiza!D12 | E20: =Analiza!E12
B21: Rozumowanie | C21: =Analiza!C13 | D21: =Analiza!D13 | E21: =Analiza!E13
B22: Zobowiązanie | C22: =Analiza!C14 | D22: =Analiza!D14 | E22: =Analiza!E14
B24: 4. ZAŁOŻENIA DO SPRAWDZENIA
B25: Założenie | C25: Jak sprawdzić | E25: Do kiedy | F25: Kto
B26: =Analiza!D26 | C26: Rozmowy z 3 klientami z ćwiartki Gwiazd przed ogłoszeniem podwyżki | E26: 15.12 | F26: Właścicielka
B27: =Analiza!C25 | C27: 5 rozmów z gabinetami (karta testu) | E27: 15.12 | F27: Właścicielka
B28: =Analiza!E26 | C28: Szkolenie PM + 2 rozmowy pod obserwacją | E28: 31.12 | F28: PM
B30: 5. TWÓJ WZORZEC DECYZYJNY
B31: =Analiza!C55
B32: ="Nawyk na przyszłość: "&Analiza!C56
B34: 6. TRZY REKOMENDACJE
B35: 1. | C35: Zróżnicuj podwyżkę według ćwiartek macierzy i przeprowadź osobistą rozmowę z klientem A, zanim wyślesz list.
B36: 2. | C36: Uczyń standard sprzedaży (skrypty, CRM, PM) priorytetem nr 1. Bez niego pozostałe dwa priorytety zależą wyłącznie od Ciebie.
B37: 3. | C37: Potwierdź segment medyczny testem 5 rozmów, zanim zmienisz stronę i komunikację.
B39: 7. PLAN NA 30 DNI
B40: Tydzień | C40: Działanie | F40: Kto
B41: Tydzień 1 | C41: Lista 20 gabinetów; rozmowy z 3 Gwiazdami o zmianach | F41: Właścicielka
B42: Tydzień 2 | C42: Rozmowa z klientem A; decyzja ze wspólnikiem | F42: Właścicielka + wspólnik
B43: Tydzień 3 | C43: Skrypty i CRM; PM prowadzi 2 rozmowy | F43: PM
B44: Tydzień 4 | C44: Wysyłka listów o zmianie cen; przegląd wyników testu | F44: Właścicielka
B46: 8. KOLEJNY KONTAKT
B47: Pytania mailowe do 14 dni po sesji. Przegląd po 30 dniach (30 min): [data i godzina].
